[doctest] run with "--help" for options
== TEST CASE ==================================================================
main.cpp(0)
an empty test that will fail because of an exception

TEST CASE FAILED!
threw exception:
  unknown exception

== TEST CASE ==================================================================
main.cpp(0)
an empty test that will fail because of a std::exception

TEST CASE FAILED!
threw exception:
  whops!

== TEST CASE ==================================================================
main.cpp(0)
normal macros

main.cpp(0) ERROR!
  CHECK( conditional_throw(true, std::runtime_error("whops!")) == 42 )
threw exception:
  whops!

main.cpp(0) ERROR!
  CHECK( Approx(0.502) == 0.501 )
with expansion:
  CHECK( Approx( 0.502 ) == 0.501 )

TEST CASE FAILED!
threw exception:
  unknown exception

== TEST CASE ==================================================================
main.cpp(0)
normal macros with std::exception

main.cpp(0) ERROR!
  CHECK( conditional_throw(true, 0) == 42 )
threw exception:
  unknown exception

main.cpp(0) ERROR!
  CHECK( Approx(0.502) == 0.501 )
with expansion:
  CHECK( Approx( 0.502 ) == 0.501 )

TEST CASE FAILED!
threw exception:
  unknown exception

== TEST CASE ==================================================================
main.cpp(0)
exceptions-related macros

main.cpp(0) ERROR!
  CHECK_THROWS( conditional_throw(false, 0) )
didn't throw at all

main.cpp(0) ERROR!
  CHECK_THROWS_AS( conditional_throw(false, 0), int )
didn't throw at all

main.cpp(0) ERROR!
  CHECK_THROWS_AS( conditional_throw(true, 0), char )
threw a different exception:
  unknown exception

main.cpp(0) ERROR!
  CHECK_NOTHROW( conditional_throw(true, 0) )
threw exception:
  unknown exception

== TEST CASE ==================================================================
main.cpp(0)
exceptions-related macros for std::exception

main.cpp(0) ERROR!
  CHECK_THROWS( conditional_throw(false, 0) )
didn't throw at all

main.cpp(0) ERROR!
  CHECK_THROWS_AS( conditional_throw(false, std::runtime_error("whops!")), std::exception )
didn't throw at all

main.cpp(0) ERROR!
  CHECK_THROWS_AS( conditional_throw(true, std::runtime_error("whops!")), int )
threw a different exception:
  whops!

main.cpp(0) FATAL ERROR!
  REQUIRE_NOTHROW( conditional_throw(true, std::runtime_error("whops!")) )
threw exception:
  whops!

===============================================================================
[doctest] test cases:    7 |    1 passed |    6 failed |    0 skipped
[doctest] assertions:   24 |   12 passed |   12 failed |
